#VRML_SIM R2022a utf8
WorldInfo {
}
Viewpoint {
  orientation -0.19666729160636387 0.18919244740493574 0.9620437590136678 1.6481774380348269
  position 2.8431242299434167 -15.320236460601192 6.995136738437962
}
TexturedBackground {
}
TexturedBackgroundLight {
}
Robot {
  translation -0.0002998555806217137 -3.070887106922922 0.17164746429322736
  rotation 0.9998494292198492 -0.0027499555529116176 -0.017133494483000288 0.006366636922469133
  children [
    DEF base_torso Shape {
      appearance OldSteel {
      }
      geometry Box {
        size 0.8 0.3 0.1
      }
    }
    DEF rightLeg2 HingeJoint {
      jointParameters HingeJointParameters {
        position 0.9809023331572737
        anchor 0 -0.18 0
      }
      device [
        RotationalMotor {
          name "rightLegVertical1"
        }
      ]
      endPoint Solid {
        translation 0 -0.18 0
        rotation -1.266915078935068e-08 0.009548688311235865 0.9999544102365543 3.1415900001209764
        children [
          DEF hip_joint Shape {
            appearance PBRAppearance {
              metalness 0
            }
            geometry Sphere {
              radius 0.05
            }
          }
          DEF leftLeftHorizintal1 HingeJoint {
            jointParameters HingeJointParameters {
              position -1.9896596038798067e-05
              axis 0 0 1
              stopCFM 2
            }
            device [
              RotationalMotor {
                name "leftLegHorizontal1"
              }
            ]
            endPoint Solid {
              translation 0.007789526771468493 0.14106784504285416 0.1104619999999995
              rotation 0.6715272078957167 0.6587914279322644 -0.339182935211592 2.562725552069243
              children [
                DEF thigh Shape {
                  appearance PBRAppearance {
                    metalness 0
                  }
                  geometry Cylinder {
                    height 0.3
                    radius 0.03
                  }
                }
                Solid {
                  translation -6.82356197588041e-05 -4.93965396133343e-05 -0.16039615067044916
                  rotation 1.6504199957195536e-05 0.9999999974064502 7.010499981817918e-05 -0.28961530717958617
                  children [
                    DEF knee Shape {
                      appearance PBRAppearance {
                        metalness 0
                      }
                      geometry Sphere {
                        radius 0.05
                      }
                    }
                    Solid {
                      translation 0.19485 0 -0.0142444
                      rotation 0 -1 0 1.5
                      children [
                        DEF leg Shape {
                          appearance PBRAppearance {
                            metalness 0
                          }
                          geometry Cylinder {
                            height 0.4
                            radius 0.03
                          }
                        }
                        Solid {
                          translation 0.000577156 0 -0.21211
                          rotation 0 1 0 0.58
                          children [
                            DEF foot Shape {
                              appearance PBRAppearance {
                                metalness 0
                              }
                              geometry Sphere {
                                radius 0.04
                              }
                            }
                          ]
                          boundingObject USE foot
                          physics DEF dog Physics {
                            mass 1
                          }
                        }
                      ]
                      boundingObject USE leg
                      physics USE dog
                    }
                  ]
                  boundingObject USE knee
                  physics USE dog
                }
              ]
              boundingObject USE thigh
              physics DEF dog Physics {
                mass 1
              }
              linearVelocity 1.50274070080946e-05 3.1925261547968386e-05 -4.405306856216387e-05
              angularVelocity -0.00032437865155189626 -3.423023925944261e-05 -0.000162628717959368
            }
          }
        ]
        name "solid(2)"
        boundingObject USE hip_joint
        physics DEF dog Physics {
          mass 1
        }
        linearVelocity 6.576789596460175e-05 1.2349731294250433e-05 -0.00014130765452057405
        angularVelocity -0.00032428201342327184 -3.2148284992539216e-05 -7.933262431980553e-07
      }
    }
    DEF rightLeg3 HingeJoint {
      jointParameters HingeJointParameters {
        position 0.9808972264042195
        anchor -0.25 -0.18 0
      }
      device [
        RotationalMotor {
          name "rightLegVertical1"
        }
      ]
      endPoint Solid {
        translation -0.25 -0.18000000000782684 -1.2247997492587194e-08
        rotation -1.2672538441805555e-08 0.009551241571323945 0.9999543858518979 3.1415900001210413
        children [
          DEF hip_joint Shape {
            appearance PBRAppearance {
              metalness 0
            }
            geometry Sphere {
              radius 0.05
            }
          }
          DEF leftLeftHorizintal1 HingeJoint {
            jointParameters HingeJointParameters {
              position -1.989167070602647e-05
              axis 0 0 1
              stopCFM 2
            }
            device [
              RotationalMotor {
                name "leftLegHorizontal1"
              }
            ]
            endPoint Solid {
              translation 0.007789526076662414 0.1410678450812202 0.11046199999999953
              rotation 0.6715272064403737 0.6587914297498846 -0.33918293456259063 2.5627255503986546
              children [
                DEF thigh Shape {
                  appearance PBRAppearance {
                    metalness 0
                  }
                  geometry Cylinder {
                    height 0.3
                    radius 0.03
                  }
                }
                Solid {
                  translation -6.82356197588041e-05 -4.93965396133343e-05 -0.16039615067044916
                  rotation 1.6504199957195536e-05 0.9999999974064502 7.010499981817918e-05 -0.28961530717958617
                  children [
                    DEF knee Shape {
                      appearance PBRAppearance {
                        metalness 0
                      }
                      geometry Sphere {
                        radius 0.05
                      }
                    }
                    Solid {
                      translation 0.19485 0 -0.0142444
                      rotation 0 -1 0 1.5
                      children [
                        DEF leg Shape {
                          appearance PBRAppearance {
                            metalness 0
                          }
                          geometry Cylinder {
                            height 0.4
                            radius 0.03
                          }
                        }
                        Solid {
                          translation 0.000577156 0 -0.21211
                          rotation 0 1 0 0.58
                          children [
                            DEF foot Shape {
                              appearance PBRAppearance {
                                metalness 0
                              }
                              geometry Sphere {
                                radius 0.04
                              }
                            }
                          ]
                          boundingObject USE foot
                          physics DEF dog Physics {
                            mass 1
                          }
                        }
                      ]
                      boundingObject USE leg
                      physics USE dog
                    }
                  ]
                  boundingObject USE knee
                  physics USE dog
                }
              ]
              boundingObject USE thigh
              physics DEF dog Physics {
                mass 1
              }
              linearVelocity 1.4979284700137306e-05 3.2845472593351146e-05 -5.023130565189155e-05
              angularVelocity -0.00032993244920796874 -3.4221657468014056e-05 -0.00016266436970708355
            }
          }
        ]
        name "solid(6)"
        boundingObject USE hip_joint
        physics DEF dog Physics {
          mass 1
        }
        linearVelocity 6.574923495677166e-05 1.2760489521411955e-05 -0.0001492511251536257
        angularVelocity -0.0003298358099641522 -3.2143192711942026e-05 -8.037584048881102e-07
      }
    }
    DEF rightLeg1 HingeJoint {
      jointParameters HingeJointParameters {
        position 0.9809076449476146
        anchor 0.25 -0.18 0
      }
      device [
        RotationalMotor {
          name "rightLegVertical1"
        }
      ]
      endPoint Solid {
        translation 0.26 -0.17999999999199268 1.273809748857074e-08
        rotation -1.266562712179822e-08 0.009546032537113301 0.9999544355933426 3.141590000120909
        children [
          DEF hip_joint Shape {
            appearance PBRAppearance {
              metalness 0
            }
            geometry Sphere {
              radius 0.05
            }
          }
          DEF leftLeftHorizintal1 HingeJoint {
            jointParameters HingeJointParameters {
              position -1.9902689782492254e-05
              axis 0 0 1
              stopCFM 2
            }
            device [
              RotationalMotor {
                name "leftLegHorizontal1"
              }
            ]
            endPoint Solid {
              translation 0.0077895276310997845 0.14106784499538677 0.1104619999999995
              rotation 0.671527209696303 0.6587914256834598 -0.33918293601455246 2.5627255541361373
              children [
                DEF thigh Shape {
                  appearance PBRAppearance {
                    metalness 0
                  }
                  geometry Cylinder {
                    height 0.3
                    radius 0.03
                  }
                }
                Solid {
                  translation -6.82356197588041e-05 -4.93965396133343e-05 -0.16039615067044916
                  rotation 1.6504199957195536e-05 0.9999999974064502 7.010499981817918e-05 -0.28961530717958617
                  children [
                    DEF knee Shape {
                      appearance PBRAppearance {
                        metalness 0
                      }
                      geometry Sphere {
                        radius 0.05
                      }
                    }
                    Solid {
                      translation 0.19485 0 -0.0142444
                      rotation 0 -1 0 1.5
                      children [
                        DEF leg Shape {
                          appearance PBRAppearance {
                            metalness 0
                          }
                          geometry Cylinder {
                            height 0.4
                            radius 0.03
                          }
                        }
                        Solid {
                          translation 0.000577156 0 -0.21211
                          rotation 0 1 0 0.58
                          children [
                            DEF foot Shape {
                              appearance PBRAppearance {
                                metalness 0
                              }
                              geometry Sphere {
                                radius 0.04
                              }
                            }
                          ]
                          boundingObject USE foot
                          physics DEF dog Physics {
                            mass 1
                          }
                        }
                      ]
                      boundingObject USE leg
                      physics USE dog
                    }
                  ]
                  boundingObject USE knee
                  physics USE dog
                }
              ]
              boundingObject USE thigh
              physics DEF dog Physics {
                mass 1
              }
              linearVelocity 1.5087178061858122e-05 3.09687092595645e-05 -3.762692839563902e-05
              angularVelocity -0.00031860448059705705 -3.424005169350821e-05 -0.00016258894197526875
            }
          }
        ]
        name "solid(4)"
        boundingObject USE hip_joint
        physics DEF dog Physics {
          mass 1
        }
        linearVelocity 6.579178301971212e-05 1.1922956465838297e-05 -0.00013304618105621557
        angularVelocity -0.0003185078470551166 -3.2153635699083734e-05 -7.828299048995282e-07
      }
    }
    DEF leftLeg2 HingeJoint {
      jointParameters HingeJointParameters {
        position 1.001220103953958
        anchor 0 0.18 0
      }
      device [
        RotationalMotor {
          name "rightLegVertical1"
        }
      ]
      endPoint Solid {
        translation 0 0.18 0
        rotation 0.9999905405325826 2.653470056376624e-06 -0.004349579096049404 0.0012201154958168653
        children [
          DEF hip_joint Shape {
            appearance PBRAppearance {
              metalness 0
            }
            geometry Sphere {
              radius 0.05
            }
          }
          DEF leftLeftHorizintal1 HingeJoint {
            jointParameters HingeJointParameters {
              position 4.391402064373222e-05
              axis 0 0 1
              stopCFM 2
            }
            device [
              RotationalMotor {
                name "leftLegHorizontal1"
              }
            ]
            endPoint Solid {
              translation 0.00778052512942966 0.1410683418101612 0.11046199999999955
              rotation 0.6715083526724223 0.6588149760349166 -0.33917452681957383 2.56270390886525
              children [
                DEF thigh Shape {
                  appearance PBRAppearance {
                    metalness 0
                  }
                  geometry Cylinder {
                    height 0.3
                    radius 0.03
                  }
                }
                Solid {
                  translation -6.82356197588041e-05 -4.93965396133343e-05 -0.16039615067044916
                  rotation 1.6504199957195536e-05 0.9999999974064502 7.010499981817918e-05 -0.28961530717958617
                  children [
                    DEF knee Shape {
                      appearance PBRAppearance {
                        metalness 0
                      }
                      geometry Sphere {
                        radius 0.05
                      }
                    }
                    Solid {
                      translation 0.19485 0 -0.0142444
                      rotation 0 -1 0 1.5
                      children [
                        DEF leg Shape {
                          appearance PBRAppearance {
                            metalness 0
                          }
                          geometry Cylinder {
                            height 0.4
                            radius 0.03
                          }
                        }
                        Solid {
                          translation 0.000577156 0 -0.21211
                          rotation 0 1 0 0.58
                          children [
                            DEF foot Shape {
                              appearance PBRAppearance {
                                metalness 0
                              }
                              geometry Sphere {
                                radius 0.04
                              }
                            }
                          ]
                          boundingObject USE foot
                          physics DEF dog Physics {
                            mass 1
                          }
                        }
                      ]
                      boundingObject USE leg
                      physics USE dog
                    }
                  ]
                  boundingObject USE knee
                  physics USE dog
                }
              ]
              boundingObject USE thigh
              physics DEF dog Physics {
                mass 1
              }
              linearVelocity 1.584422298090638e-05 4.427547000823034e-06 -2.2913463226814195e-05
              angularVelocity 0.0001784673403270614 -3.343082301597419e-05 0.00016053452968478891
            }
          }
        ]
        name "solid(5)"
        boundingObject USE hip_joint
        physics DEF dog Physics {
          mass 1
        }
        linearVelocity 6.59466002267628e-05 1.1997156650238595e-05 -7.711270061975029e-05
        angularVelocity 0.00017836720837749448 -3.219398952780671e-05 -8.335148330429474e-07
      }
    }
    DEF leftLeg3 HingeJoint {
      jointParameters HingeJointParameters {
        position 1.0012201142332184
        anchor -0.25 0.18 0
      }
      device [
        RotationalMotor {
          name "rightLegVertical1"
        }
      ]
      endPoint Solid {
        translation -0.25 0.17999999999998398 1.6055400039156358e-09
        rotation 0.9999905406919684 2.6534700567963748e-06 -0.004349542452250805 0.001220125774738302
        children [
          DEF hip_joint Shape {
            appearance PBRAppearance {
              metalness 0
            }
            geometry Sphere {
              radius 0.05
            }
          }
          DEF leftLeftHorizintal1 HingeJoint {
            jointParameters HingeJointParameters {
              position 4.392483363709647e-05
              axis 0 0 1
              stopCFM 2
            }
            device [
              RotationalMotor {
                name "leftLegHorizontal1"
              }
            ]
            endPoint Solid {
              translation 0.007780523604058617 0.14106834189429196 0.11046199999999956
              rotation 0.6715083494772546 0.6588149800252058 -0.3391745253947016 2.562703905197758
              children [
                DEF thigh Shape {
                  appearance PBRAppearance {
                    metalness 0
                  }
                  geometry Cylinder {
                    height 0.3
                    radius 0.03
                  }
                }
                Solid {
                  translation -6.82356197588041e-05 -4.93965396133343e-05 -0.16039615067044916
                  rotation 1.6504199957195536e-05 0.9999999974064502 7.010499981817918e-05 -0.28961530717958617
                  children [
                    DEF knee Shape {
                      appearance PBRAppearance {
                        metalness 0
                      }
                      geometry Sphere {
                        radius 0.05
                      }
                    }
                    Solid {
                      translation 0.19485 0 -0.0142444
                      rotation 0 -1 0 1.5
                      children [
                        DEF leg Shape {
                          appearance PBRAppearance {
                            metalness 0
                          }
                          geometry Cylinder {
                            height 0.4
                            radius 0.03
                          }
                        }
                        Solid {
                          translation 0.000577156 0 -0.21211
                          rotation 0 1 0 0.58
                          children [
                            DEF foot Shape {
                              appearance PBRAppearance {
                                metalness 0
                              }
                              geometry Sphere {
                                radius 0.04
                              }
                            }
                          ]
                          boundingObject USE foot
                          physics DEF dog Physics {
                            mass 1
                          }
                        }
                      ]
                      boundingObject USE leg
                      physics USE dog
                    }
                  ]
                  boundingObject USE knee
                  physics USE dog
                }
              ]
              boundingObject USE thigh
              physics DEF dog Physics {
                mass 1
              }
              linearVelocity 1.5795250595824992e-05 4.511558936499682e-06 -3.0683914746077555e-05
              angularVelocity 0.00017855051957987509 -3.3434921988760965e-05 0.00016070799835945653
            }
          }
        ]
        name "solid(3)"
        boundingObject USE hip_joint
        physics DEF dog Physics {
          mass 1
        }
        linearVelocity 6.594860316475448e-05 1.2143114179934856e-05 -8.502947682552531e-05
        angularVelocity 0.00017841080813241206 -3.219537216092582e-05 -8.346794263536238e-07
      }
    }
    DEF leftLeg1 HingeJoint {
      jointParameters HingeJointParameters {
        position 1.0012200948521328
        anchor 0.25 0.18 0
      }
      device [
        RotationalMotor {
          name "rightLegVertical1"
        }
      ]
      endPoint Solid {
        translation 0.25 0.18000000000001598 -1.605519999578715e-09
        rotation 0.9999905403914499 2.6534700560053337e-06 -0.004349611543010318 0.0012201063942712104
        children [
          DEF hip_joint Shape {
            appearance PBRAppearance {
              metalness 0
            }
            geometry Sphere {
              radius 0.05
            }
          }
          DEF leftLeftHorizintal1 HingeJoint {
            jointParameters HingeJointParameters {
              position 4.390540241614961e-05
              axis 0 0 1
              stopCFM 2
            }
            device [
              RotationalMotor {
                name "leftLegHorizontal1"
              }
            ]
            endPoint Solid {
              translation 0.007780526345188734 0.14106834174310684 0.11046199999999955
              rotation 0.6715083552190514 0.6588149728545559 -0.3391745279552329 2.5627039117883337
              children [
                DEF thigh Shape {
                  appearance PBRAppearance {
                    metalness 0
                  }
                  geometry Cylinder {
                    height 0.3
                    radius 0.03
                  }
                }
                Solid {
                  translation -6.82356197588041e-05 -4.93965396133343e-05 -0.16039615067044916
                  rotation 1.6504199957195536e-05 0.9999999974064502 7.010499981817918e-05 -0.28961530717958617
                  children [
                    DEF knee Shape {
                      appearance PBRAppearance {
                        metalness 0
                      }
                      geometry Sphere {
                        radius 0.05
                      }
                    }
                    Solid {
                      translation 0.19485 0 -0.0142444
                      rotation 0 -1 0 1.5
                      children [
                        DEF leg Shape {
                          appearance PBRAppearance {
                            metalness 0
                          }
                          geometry Cylinder {
                            height 0.4
                            radius 0.03
                          }
                        }
                        Solid {
                          translation 0.000577156 0 -0.21211
                          rotation 0 1 0 0.58
                          children [
                            DEF foot Shape {
                              appearance PBRAppearance {
                                metalness 0
                              }
                              geometry Sphere {
                                radius 0.04
                              }
                            }
                          ]
                          boundingObject USE foot
                          physics DEF dog Physics {
                            mass 1
                          }
                        }
                      ]
                      boundingObject USE leg
                      physics USE dog
                    }
                  ]
                  boundingObject USE knee
                  physics USE dog
                }
              ]
              boundingObject USE thigh
              physics DEF dog Physics {
                mass 1
              }
              linearVelocity 1.5892883897994588e-05 4.295493918128551e-06 -1.5145301667928445e-05
              angularVelocity 0.0001783762231738256 -3.342810055054736e-05 0.00016038250361216703
            }
          }
        ]
        name "solid(1)"
        boundingObject USE hip_joint
        physics DEF dog Physics {
          mass 1
        }
        linearVelocity 6.594770578601317e-05 1.1826847818269926e-05 -6.919588233472495e-05
        angularVelocity 0.00017832030579256747 -3.2193201767061183e-05 -8.339482422958787e-07
      }
    }
  ]
  boundingObject USE base_torso
  physics DEF dog Physics {
    mass 1
  }
  controller ""
  linearVelocity 6.58543401306968e-05 1.216738966138564e-05 -0.00010922129265208014
  angularVelocity 0.00017836332957882987 -3.218014501179296e-05 -8.19497961852173e-07
}
Forest {
  density 0.08
}
Floor {
  translation 0 0 -0.01
}
